<?xml version="1.0" ?>
<robot xmlns:xacro="http://ros.org/wiki/xacro" name="ar3" >

    <!-- include materials / colors -->
  <xacro:include filename="$(find tpm_description)/urdf/materials.xacro" />

    <link name="base_link">
      <visual>
        <origin xyz="0 0 0" rpy="0 0 0" />
        <geometry>
          <mesh filename="package://tpm_description/meshes/ar3/base_link.stl" />
        </geometry>
        <material name="orange"/>
      </visual>
    </link>

    <joint name="joint1" type="revolute">
      <origin xyz="0 0 0.003445" rpy="0 0 0" />
      <parent link="base_link" />
      <child link="link1" />
      <axis xyz="0 0 -1" />
      <limit lower="${-160.0 * pi/180.0}" upper="${120.0 * pi/180.0}" effort="0" velocity="0"/>
    </joint>

    <link name="link1">
      <visual>
        <origin xyz="0 0 0" rpy="0 0 0" />
        <geometry>
          <mesh filename="package://tpm_description/meshes/ar3/link_1.stl" />
        </geometry>
        <material name="blue"/>
      </visual>
    </link>

    <joint name="joint2" type="revolute">
      <!--we define 0 deg of link2 as standing up (point to z+). not lying on the ground-->
      <!--thus we wet the pitch of origin as -pi/2 -->
      <origin xyz="0.064146 0 0.16608" rpy="${-pi/2.0} ${-pi/2.0} 0" />
      <parent link="link1" />
      <child link="link2" />
      <axis xyz="0 0 1" />
      <limit lower="${-33 * pi/180.0}" upper="${90 * pi/180.0}" effort="0" velocity="0"/>
    </joint>

    <link name="link2">
      <visual>
        <origin xyz="0 0 0" rpy="0 0 0" />
        <geometry>
          <mesh filename="package://tpm_description/meshes/ar3/link_2.stl" />
        </geometry>
        <material name="green"/>
      </visual>
    </link>

    <joint name="joint3" type="revolute">
      <!--we define 0 deg of link3 as 90deg related to link2.-->
      <!--thus we wet the yaw of origin as pi/2 -->
      <origin xyz="0.3050019501576998 0 0" rpy="0 0 ${pi/2}" />
      <parent link="link2" />
      <child link="link3" />
      <axis xyz="0 0 1" />
      <limit lower="${-130 * pi/180.0}" upper="${50 * pi/180.0}" effort="0" velocity="0"/>
    </joint>

    <link name="link3">
      <visual>
        <origin xyz="0 0 0" rpy="0 0 0" />
        <geometry>
          <mesh filename="package://tpm_description/meshes/ar3/link_3.stl" />
        </geometry>
        <material name="red"/>
      </visual>
    </link>

    <joint name="joint4" type="revolute">
      <origin xyz="0 0 0.00675" rpy="0 ${pi/2.0} 0"/>
      <parent link="link3" />
      <child link="link4" />
      <axis xyz="0 0 1" />
      <limit lower="${-90 * pi/180.0}" upper="${80 * pi/180.0}" effort="0" velocity="0"/>
    </joint>

    <link name="link4">
      <visual>
        <origin xyz="0 0 0" rpy="0 0 0" />
        <geometry>
          <mesh filename="package://tpm_description/meshes/ar3/link_4.stl" />
        </geometry>
        <material name="blue"/>
      </visual>
    </link>

    <joint name="joint5" type="revolute">
      <origin xyz="0 0 0.22225" rpy="0 ${-pi/2.0} 0" />
      <parent link="link4" />
      <child link="link5" />
      <axis xyz="0 0 1" />
      <limit lower="${-50 * pi/180.0}" upper="${120 * pi/180.0}" effort="0" velocity="0"/>
    </joint>

    <link name="link5">
      <visual>
        <origin xyz="0 0 0" rpy="0 0 0" />
        <geometry>
          <mesh filename="package://tpm_description/meshes/ar3/link_5.stl" />
        </geometry>
        <material name="green"/>
      </visual>
    </link>

    <joint name="joint6" type="revolute">
      <origin xyz="0.02117 0 0 " rpy="0 ${pi/2.0} 0" />
      <parent link="link5" />
      <child link="link6" />
      <axis xyz="0 0 1" />
      <limit lower="${-170 * pi/180.0}" upper="${170 * pi/180.0}" effort="0" velocity="0"/>
    </joint>

    <link name="link6">
      <visual>
        <origin xyz="0 0 0" rpy="0 0 0" />
        <geometry>
          <mesh filename="package://tpm_description/meshes/ar3/link_6.stl" />
        </geometry>
        <material name="orange"/>
      </visual>
    </link>


</robot>
